Script started on ÂªøÂçÅ‰∏ÉÂπ¥ÂçÅ‰∫åÊúàÂªø‰∫åÊó• (ÈÄ±‰∫î) ÂçÅ‰∫îÊôÇÂªø‰∏ÉÂàÜ54Áßí
]0;jlo@psme-001: ~/Pyroot/uionejlo@psme-001:~/Pyroot/uione$ cd tmsone
]0;jlo@psme-001: ~/Pyroot/uione/tmsonejlo@psme-001:~/Pyroot/uione/tmsone$ . [K[Kcd ..
]0;jlo@psme-001: ~/Pyroot/uionejlo@psme-001:~/Pyroot/uione$ s[K. uienv/bin/actibate[K[K[K[Kvate
(uienv) ]0;jlo@psme-001: ~/Pyroot/uionejlo@psme-001:~/Pyroot/uione$ cd tmsone
(uienv) ]0;jlo@psme-001: ~/Pyroot/uione/tmsonejlo@psme-001:~/Pyroot/uione/tmsone$ ls
db.sqlite3  [0m[01;32mmanage.py[0m  outputfile.txt  [01;34mtms[0m  [01;34mtms.cschang[0m  typescript
(uienv) ]0;jlo@psme-001: ~/Pyroot/uione/tmsonejlo@psme-001:~/Pyroot/uione/tmsone$ python manage.py startapp home
(uienv) ]0;jlo@psme-001: ~/Pyroot/uione/tmsonejlo@psme-001:~/Pyroot/uione/tmsone$ ls
db.sqlite3  [0m[01;34mhome[0m  [01;32mmanage.py[0m  outputfile.txt  [01;34mtms[0m  [01;34mtms.cschang[0m  typescript
(uienv) ]0;jlo@psme-001: ~/Pyroot/uione/tmsonejlo@psme-001:~/Pyroot/uione/tmsone$ python manage.py makemigrations home
Traceback (most recent call last):
  File "manage.py", line 15, in <module>
    execute_from_command_line(sys.argv)
  File "/home/jlo/Pyroot/uione/uienv/lib/python3.5/site-packages/django/core/management/__init__.py", line 371, in execute_from_command_line
    utility.execute()
  File "/home/jlo/Pyroot/uione/uienv/lib/python3.5/site-packages/django/core/management/__init__.py", line 347, in execute
    django.setup()
  File "/home/jlo/Pyroot/uione/uienv/lib/python3.5/site-packages/django/__init__.py", line 24, in setup
    apps.populate(settings.INSTALLED_APPS)
  File "/home/jlo/Pyroot/uione/uienv/lib/python3.5/site-packages/django/apps/registry.py", line 112, in populate
    app_config.import_models()
  File "/home/jlo/Pyroot/uione/uienv/lib/python3.5/site-packages/django/apps/config.py", line 198, in import_models
    self.models_module = import_module(models_module_name)
  File "/usr/lib/python3.5/importlib/__init__.py", line 126, in import_module
    return _bootstrap._gcd_import(name[level:], package, level)
  File "<frozen importlib._bootstrap>", line 986, in _gcd_import
  File "<frozen importlib._bootstrap>", line 969, in _find_and_load
  File "<frozen importlib._bootstrap>", line 958, in _find_and_load_unlocked
  File "<frozen importlib._bootstrap>", line 673, in _load_unlocked
  File "<frozen importlib._bootstrap_external>", line 665, in exec_module
  File "<frozen importlib._bootstrap>", line 222, in _call_with_frames_removed
  File "/home/jlo/Pyroot/uione/tmsone/home/models.py", line 4, in <module>
    class Post(models.Model):
  File "/home/jlo/Pyroot/uione/tmsone/home/models.py", line 5, in Post
    author = models.ForeignKey('auth.User')
TypeError: __init__() missing 1 required positional argument: 'on_delete'
(uienv) ]0;jlo@psme-001: ~/Pyroot/uione/tmsonejlo@psme-001:~/Pyroot/uione/tmsone$ python manage.py makemigrations home
Traceback (most recent call last):
  File "manage.py", line 15, in <module>
    execute_from_command_line(sys.argv)
  File "/home/jlo/Pyroot/uione/uienv/lib/python3.5/site-packages/django/core/management/__init__.py", line 371, in execute_from_command_line
    utility.execute()
  File "/home/jlo/Pyroot/uione/uienv/lib/python3.5/site-packages/django/core/management/__init__.py", line 347, in execute
    django.setup()
  File "/home/jlo/Pyroot/uione/uienv/lib/python3.5/site-packages/django/__init__.py", line 24, in setup
    apps.populate(settings.INSTALLED_APPS)
  File "/home/jlo/Pyroot/uione/uienv/lib/python3.5/site-packages/django/apps/registry.py", line 112, in populate
    app_config.import_models()
  File "/home/jlo/Pyroot/uione/uienv/lib/python3.5/site-packages/django/apps/config.py", line 198, in import_models
    self.models_module = import_module(models_module_name)
  File "/usr/lib/python3.5/importlib/__init__.py", line 126, in import_module
    return _bootstrap._gcd_import(name[level:], package, level)
  File "<frozen importlib._bootstrap>", line 986, in _gcd_import
  File "<frozen importlib._bootstrap>", line 969, in _find_and_load
  File "<frozen importlib._bootstrap>", line 958, in _find_and_load_unlocked
  File "<frozen importlib._bootstrap>", line 673, in _load_unlocked
  File "<frozen importlib._bootstrap_external>", line 665, in exec_module
  File "<frozen importlib._bootstrap>", line 222, in _call_with_frames_removed
  File "/home/jlo/Pyroot/uione/tmsone/home/models.py", line 4, in <module>
    class Post(models.Model):
  File "/home/jlo/Pyroot/uione/tmsone/home/models.py", line 6, in Post
    title = models.charField(max_length=200)
AttributeError: module 'django.db.models' has no attribute 'charField'
(uienv) ]0;jlo@psme-001: ~/Pyroot/uione/tmsonejlo@psme-001:~/Pyroot/uione/tmsone$ python manage.py makemigrations home
[36;1mMigrations for 'home':[0m
  [1mhome/migrations/0001_initial.py[0m
    - Create model Post
(uienv) ]0;jlo@psme-001: ~/Pyroot/uione/tmsonejlo@psme-001:~/Pyroot/uione/tmsone$ python manage.py makemigrations home[1P[1P[1P[1P[C[C[C[C[C[C[1@e[1P[1P[1P[1P home
[36;1mOperations to perform:[0m
[1m  Apply all migrations: [0mhome
[36;1mRunning migrations:[0m
  Applying home.0001_initial...[32;1m OK[0m
(uienv) ]0;jlo@psme-001: ~/Pyroot/uione/tmsonejlo@psme-001:~/Pyroot/uione/tmsone$ python manage.py createsuperuser
Username (leave blank to use 'jlo'): 
Email address: james_lo@accton.com
Password: 
Password (again): 
[31;1mThis password is too short. It must contain at least 8 characters.
[0mPassword: 
Password (again): 
Superuser created successfully.
(uienv) ]0;jlo@psme-001: ~/Pyroot/uione/tmsonejlo@psme-001:~/Pyroot/uione/tmsone$ fg
bash: fg: current: no such job
(uienv) ]0;jlo@psme-001: ~/Pyroot/uione/tmsonejlo@psme-001:~/Pyroot/uione/tmsone$ fgpython manage.py createsuperuser[3Pmigrate home[7@akemigrations[C[C[C[C[C
Traceback (most recent call last):
  File "manage.py", line 15, in <module>
    execute_from_command_line(sys.argv)
  File "/home/jlo/Pyroot/uione/uienv/lib/python3.5/site-packages/django/core/management/__init__.py", line 371, in execute_from_command_line
    utility.execute()
  File "/home/jlo/Pyroot/uione/uienv/lib/python3.5/site-packages/django/core/management/__init__.py", line 347, in execute
    django.setup()
  File "/home/jlo/Pyroot/uione/uienv/lib/python3.5/site-packages/django/__init__.py", line 24, in setup
    apps.populate(settings.INSTALLED_APPS)
  File "/home/jlo/Pyroot/uione/uienv/lib/python3.5/site-packages/django/apps/registry.py", line 112, in populate
    app_config.import_models()
  File "/home/jlo/Pyroot/uione/uienv/lib/python3.5/site-packages/django/apps/config.py", line 198, in import_models
    self.models_module = import_module(models_module_name)
  File "/usr/lib/python3.5/importlib/__init__.py", line 126, in import_module
    return _bootstrap._gcd_import(name[level:], package, level)
  File "<frozen importlib._bootstrap>", line 986, in _gcd_import
  File "<frozen importlib._bootstrap>", line 969, in _find_and_load
  File "<frozen importlib._bootstrap>", line 958, in _find_and_load_unlocked
  File "<frozen importlib._bootstrap>", line 673, in _load_unlocked
  File "<frozen importlib._bootstrap_external>", line 665, in exec_module
  File "<frozen importlib._bootstrap>", line 222, in _call_with_frames_removed
  File "/home/jlo/Pyroot/uione/tmsone/home/models.py", line 4, in <module>
    class Post(models.Model):
  File "/home/jlo/Pyroot/uione/tmsone/home/models.py", line 5, in Post
    author = models.ForeignKey('auth.User')
TypeError: __init__() missing 1 required positional argument: 'on_delete'
(uienv) ]0;jlo@psme-001: ~/Pyroot/uione/tmsonejlo@psme-001:~/Pyroot/uione/tmsone$ python manage.py makemigrations home[K
(uienv) ]0;jlo@psme-001: ~/Pyroot/uione/tmsonejlo@psme-001:~/Pyroot/uione/tmsone$ 
(uienv) ]0;jlo@psme-001: ~/Pyroot/uione/tmsonejlo@psme-001:~/Pyroot/uione/tmsone$ 
(uienv) ]0;jlo@psme-001: ~/Pyroot/uione/tmsonejlo@psme-001:~/Pyroot/uione/tmsone$ ls
db.sqlite3  [0m[01;34mhome[0m  [01;32mmanage.py[0m  outputfile.txt  [01;34mtms[0m  [01;34mtms.cschang[0m  typescript
(uienv) ]0;jlo@psme-001: ~/Pyroot/uione/tmsonejlo@psme-001:~/Pyroot/uione/tmsone$ cd home
(uienv) ]0;jlo@psme-001: ~/Pyroot/uione/tmsone/homejlo@psme-001:~/Pyroot/uione/tmsone/home$ ls
admin.py  apps.py  __init__.py  [0m[01;34mmigrations[0m  models.py  [01;34m__pycache__[0m  tests.py  views.py
(uienv) ]0;jlo@psme-001: ~/Pyroot/uione/tmsone/homejlo@psme-001:~/Pyroot/uione/tmsone/home$ emacs models.py
^X^C(uienv) ]0;jlo@psme-001: ~/Pyroot/uione/tmsone/homejlo@psme-001:~/Pyroot/uione/tmsone/home$ emacs models.pyls[Kcd homels[Kpython manage.py makemigrations home
python: can't open file 'manage.py': [Errno 2] No such file or directory
(uienv) ]0;jlo@psme-001: ~/Pyroot/uione/tmsone/homejlo@psme-001:~/Pyroot/uione/tmsone/home$ cd ..
(uienv) ]0;jlo@psme-001: ~/Pyroot/uione/tmsonejlo@psme-001:~/Pyroot/uione/tmsone$ cd ..python manage.py makemigrations home
Traceback (most recent call last):
  File "manage.py", line 15, in <module>
    execute_from_command_line(sys.argv)
  File "/home/jlo/Pyroot/uione/uienv/lib/python3.5/site-packages/django/core/management/__init__.py", line 371, in execute_from_command_line
    utility.execute()
  File "/home/jlo/Pyroot/uione/uienv/lib/python3.5/site-packages/django/core/management/__init__.py", line 347, in execute
    django.setup()
  File "/home/jlo/Pyroot/uione/uienv/lib/python3.5/site-packages/django/__init__.py", line 24, in setup
    apps.populate(settings.INSTALLED_APPS)
  File "/home/jlo/Pyroot/uione/uienv/lib/python3.5/site-packages/django/apps/registry.py", line 112, in populate
    app_config.import_models()
  File "/home/jlo/Pyroot/uione/uienv/lib/python3.5/site-packages/django/apps/config.py", line 198, in import_models
    self.models_module = import_module(models_module_name)
  File "/usr/lib/python3.5/importlib/__init__.py", line 126, in import_module
    return _bootstrap._gcd_import(name[level:], package, level)
  File "<frozen importlib._bootstrap>", line 986, in _gcd_import
  File "<frozen importlib._bootstrap>", line 969, in _find_and_load
  File "<frozen importlib._bootstrap>", line 958, in _find_and_load_unlocked
  File "<frozen importlib._bootstrap>", line 673, in _load_unlocked
  File "<frozen importlib._bootstrap_external>", line 665, in exec_module
  File "<frozen importlib._bootstrap>", line 222, in _call_with_frames_removed
  File "/home/jlo/Pyroot/uione/tmsone/home/models.py", line 4, in <module>
    class Post(models.Model):
  File "/home/jlo/Pyroot/uione/tmsone/home/models.py", line 8, in Post
    title = models.charField(max_length=200)
AttributeError: module 'django.db.models' has no attribute 'charField'
(uienv) ]0;jlo@psme-001: ~/Pyroot/uione/tmsonejlo@psme-001:~/Pyroot/uione/tmsone$ python manage.py makemigrations home
No changes detected in app 'home'
(uienv) ]0;jlo@psme-001: ~/Pyroot/uione/tmsonejlo@psme-001:~/Pyroot/uione/tmsone$ python manage.py makemigrations homecd ..[Kpython manage.py makemigrations home[21Pemacs models.pyls[Kemacs models.pypython manage.py makemigrations homecd ..[Kpython manage.py makemigrations home[Kpython manage.py makemigrations homecd ..[Kpython manage.py makemigrations home[21Pemacs models.pyls[Kcd homels[Kpython manage.py makemigrations homefg[Kpython manage.py createsuperuser[3Pmigrate home
[36;1mOperations to perform:[0m
[1m  Apply all migrations: [0mhome
[36;1mRunning migrations:[0m
  No migrations to apply.
(uienv) ]0;jlo@psme-001: ~/Pyroot/uione/tmsonejlo@psme-001:~/Pyroot/uione/tmsone$ python manage.py migrate home[7@akemigrations[C[C[C[C[C
You are trying to add a non-nullable field 'title' to post without a default; we can't do that (the database needs something to populate existing rows).
Please select a fix:
 1) Provide a one-off default now (will be set on all existing rows with a null value for this column)
 2) Quit, and let me add a default in models.py
Select an option: 2
(uienv) ]0;jlo@psme-001: ~/Pyroot/uione/tmsonejlo@psme-001:~/Pyroot/uione/tmsone$ python manage.py makemigrations home
You are trying to add a non-nullable field 'title' to post without a default; we can't do that (the database needs something to populate existing rows).
Please select a fix:
 1) Provide a one-off default now (will be set on all existing rows with a null value for this column)
 2) Quit, and let me add a default in models.py
Select an option: 1
Please enter the default value now, as valid Python
The datetime and django.utils.timezone modules are available, so you can do e.g. timezone.now
Type 'exit' to exit this prompt
>>> Bol  log
Invalid input: name 'Blog' is not defined
>>> null
Invalid input: name 'null' is not defined
>>> timezone.now
[36;1mMigrations for 'home':[0m
  [1mhome/migrations/0002_post_title.py[0m
    - Add field title to post
(uienv) ]0;jlo@psme-001: ~/Pyroot/uione/tmsonejlo@psme-001:~/Pyroot/uione/tmsone$ python manage.py makemigrations home
No changes detected in app 'home'
(uienv) ]0;jlo@psme-001: ~/Pyroot/uione/tmsonejlo@psme-001:~/Pyroot/uione/tmsone$ python manage.py makemigrations home[7Pigrate[C[C[C[C[C
[36;1mOperations to perform:[0m
[1m  Apply all migrations: [0mhome
[36;1mRunning migrations:[0m
  Applying home.0002_post_title...[32;1m OK[0m
(uienv) ]0;jlo@psme-001: ~/Pyroot/uione/tmsonejlo@psme-001:~/Pyroot/uione/tmsone$ python manage.py migrate home[K[K[K[K[K[K[K[K[K[K[K[Krunsere[Kver
Performing system checks...

System check identified no issues (0 silenced).
December 22, 2017 - 08:42:02
Django version 2.0, using settings 'tms.settings'
Starting development server at http://127.0.0.1:8000/
Quit the server with CONTROL-C.
[31;1mError: That port is already in use.
[0m(uienv) ]0;jlo@psme-001: ~/Pyroot/uione/tmsonejlo@psme-001:~/Pyroot/uione/tmsone$ ^C
(uienv) ]0;jlo@psme-001: ~/Pyroot/uione/tmsonejlo@psme-001:~/Pyroot/uione/tmsone$ 
(uienv) ]0;jlo@psme-001: ~/Pyroot/uione/tmsonejlo@psme-001:~/Pyroot/uione/tmsone$ fg
bash: fg: current: no such job
(uienv) ]0;jlo@psme-001: ~/Pyroot/uione/tmsonejlo@psme-001:~/Pyroot/uione/tmsone$ 
(uienv) ]0;jlo@psme-001: ~/Pyroot/uione/tmsonejlo@psme-001:~/Pyroot/uione/tmsone$ 
(uienv) ]0;jlo@psme-001: ~/Pyroot/uione/tmsonejlo@psme-001:~/Pyroot/uione/tmsone$ fgpython manage.py runserver
Performing system checks...

Unhandled exception in thread started by <function check_errors.<locals>.wrapper at 0x7f02be8c7ae8>
Traceback (most recent call last):
  File "/home/jlo/Pyroot/uione/uienv/lib/python3.5/site-packages/django/utils/autoreload.py", line 225, in wrapper
    fn(*args, **kwargs)
  File "/home/jlo/Pyroot/uione/uienv/lib/python3.5/site-packages/django/core/management/commands/runserver.py", line 120, in inner_run
    self.check(display_num_errors=True)
  File "/home/jlo/Pyroot/uione/uienv/lib/python3.5/site-packages/django/core/management/base.py", line 364, in check
    include_deployment_checks=include_deployment_checks,
  File "/home/jlo/Pyroot/uione/uienv/lib/python3.5/site-packages/django/core/management/base.py", line 351, in _run_checks
    return checks.run_checks(**kwargs)
  File "/home/jlo/Pyroot/uione/uienv/lib/python3.5/site-packages/django/core/checks/registry.py", line 73, in run_checks
    new_errors = check(app_configs=app_configs)
  File "/home/jlo/Pyroot/uione/uienv/lib/python3.5/site-packages/django/core/checks/urls.py", line 40, in check_url_namespaces_unique
    all_namespaces = _load_all_namespaces(resolver)
  File "/home/jlo/Pyroot/uione/uienv/lib/python3.5/site-packages/django/core/checks/urls.py", line 57, in _load_all_namespaces
    url_patterns = getattr(resolver, 'url_patterns', [])
  File "/home/jlo/Pyroot/uione/uienv/lib/python3.5/site-packages/django/utils/functional.py", line 36, in __get__
    res = instance.__dict__[self.name] = self.func(instance)
  File "/home/jlo/Pyroot/uione/uienv/lib/python3.5/site-packages/django/urls/resolvers.py", line 536, in url_patterns
    patterns = getattr(self.urlconf_module, "urlpatterns", self.urlconf_module)
  File "/home/jlo/Pyroot/uione/uienv/lib/python3.5/site-packages/django/utils/functional.py", line 36, in __get__
    res = instance.__dict__[self.name] = self.func(instance)
  File "/home/jlo/Pyroot/uione/uienv/lib/python3.5/site-packages/django/urls/resolvers.py", line 529, in urlconf_module
    return import_module(self.urlconf_name)
  File "/usr/lib/python3.5/importlib/__init__.py", line 126, in import_module
    return _bootstrap._gcd_import(name[level:], package, level)
  File "<frozen importlib._bootstrap>", line 986, in _gcd_import
  File "<frozen importlib._bootstrap>", line 969, in _find_and_load
  File "<frozen importlib._bootstrap>", line 958, in _find_and_load_unlocked
  File "<frozen importlib._bootstrap>", line 673, in _load_unlocked
  File "<frozen importlib._bootstrap_external>", line 665, in exec_module
  File "<frozen importlib._bootstrap>", line 222, in _call_with_frames_removed
  File "/home/jlo/Pyroot/uione/tmsone/tms/urls.py", line 21, in <module>
    path('', include('home.urls')),
NameError: name 'include' is not defined

Performing system checks...

Unhandled exception in thread started by <function check_errors.<locals>.wrapper at 0x7f0c5da0aae8>
Traceback (most recent call last):
  File "/home/jlo/Pyroot/uione/uienv/lib/python3.5/site-packages/django/utils/autoreload.py", line 225, in wrapper
    fn(*args, **kwargs)
  File "/home/jlo/Pyroot/uione/uienv/lib/python3.5/site-packages/django/core/management/commands/runserver.py", line 120, in inner_run
    self.check(display_num_errors=True)
  File "/home/jlo/Pyroot/uione/uienv/lib/python3.5/site-packages/django/core/management/base.py", line 364, in check
    include_deployment_checks=include_deployment_checks,
  File "/home/jlo/Pyroot/uione/uienv/lib/python3.5/site-packages/django/core/management/base.py", line 351, in _run_checks
    return checks.run_checks(**kwargs)
  File "/home/jlo/Pyroot/uione/uienv/lib/python3.5/site-packages/django/core/checks/registry.py", line 73, in run_checks
    new_errors = check(app_configs=app_configs)
  File "/home/jlo/Pyroot/uione/uienv/lib/python3.5/site-packages/django/core/checks/urls.py", line 13, in check_url_config
    return check_resolver(resolver)
  File "/home/jlo/Pyroot/uione/uienv/lib/python3.5/site-packages/django/core/checks/urls.py", line 23, in check_resolver
    return check_method()
  File "/home/jlo/Pyroot/uione/uienv/lib/python3.5/site-packages/django/urls/resolvers.py", line 397, in check
    for pattern in self.url_patterns:
  File "/home/jlo/Pyroot/uione/uienv/lib/python3.5/site-packages/django/utils/functional.py", line 36, in __get__
    res = instance.__dict__[self.name] = self.func(instance)
  File "/home/jlo/Pyroot/uione/uienv/lib/python3.5/site-packages/django/urls/resolvers.py", line 536, in url_patterns
    patterns = getattr(self.urlconf_module, "urlpatterns", self.urlconf_module)
  File "/home/jlo/Pyroot/uione/uienv/lib/python3.5/site-packages/django/utils/functional.py", line 36, in __get__
    res = instance.__dict__[self.name] = self.func(instance)
  File "/home/jlo/Pyroot/uione/uienv/lib/python3.5/site-packages/django/urls/resolvers.py", line 529, in urlconf_module
    return import_module(self.urlconf_name)
  File "/usr/lib/python3.5/importlib/__init__.py", line 126, in import_module
    return _bootstrap._gcd_import(name[level:], package, level)
  File "<frozen importlib._bootstrap>", line 986, in _gcd_import
  File "<frozen importlib._bootstrap>", line 969, in _find_and_load
  File "<frozen importlib._bootstrap>", line 958, in _find_and_load_unlocked
  File "<frozen importlib._bootstrap>", line 673, in _load_unlocked
  File "<frozen importlib._bootstrap_external>", line 665, in exec_module
  File "<frozen importlib._bootstrap>", line 222, in _call_with_frames_removed
  File "/home/jlo/Pyroot/uione/tmsone/tms/urls.py", line 21, in <module>
    path(r'', include('home.urls')),
NameError: name 'include' is not defined
^[[A^[[B^C(uienv) ]0;jlo@psme-001: ~/Pyroot/uione/tmsonejlo@psme-001:~/Pyroot/uione/tmsone$ python manage.py runserver
Performing system checks...

Unhandled exception in thread started by <function check_errors.<locals>.wrapper at 0x7f78d1c89ae8>
Traceback (most recent call last):
  File "/home/jlo/Pyroot/uione/uienv/lib/python3.5/site-packages/django/utils/autoreload.py", line 225, in wrapper
    fn(*args, **kwargs)
  File "/home/jlo/Pyroot/uione/uienv/lib/python3.5/site-packages/django/core/management/commands/runserver.py", line 120, in inner_run
    self.check(display_num_errors=True)
  File "/home/jlo/Pyroot/uione/uienv/lib/python3.5/site-packages/django/core/management/base.py", line 364, in check
    include_deployment_checks=include_deployment_checks,
  File "/home/jlo/Pyroot/uione/uienv/lib/python3.5/site-packages/django/core/management/base.py", line 351, in _run_checks
    return checks.run_checks(**kwargs)
  File "/home/jlo/Pyroot/uione/uienv/lib/python3.5/site-packages/django/core/checks/registry.py", line 73, in run_checks
    new_errors = check(app_configs=app_configs)
  File "/home/jlo/Pyroot/uione/uienv/lib/python3.5/site-packages/django/core/checks/urls.py", line 40, in check_url_namespaces_unique
    all_namespaces = _load_all_namespaces(resolver)
  File "/home/jlo/Pyroot/uione/uienv/lib/python3.5/site-packages/django/core/checks/urls.py", line 57, in _load_all_namespaces
    url_patterns = getattr(resolver, 'url_patterns', [])
  File "/home/jlo/Pyroot/uione/uienv/lib/python3.5/site-packages/django/utils/functional.py", line 36, in __get__
    res = instance.__dict__[self.name] = self.func(instance)
  File "/home/jlo/Pyroot/uione/uienv/lib/python3.5/site-packages/django/urls/resolvers.py", line 536, in url_patterns
    patterns = getattr(self.urlconf_module, "urlpatterns", self.urlconf_module)
  File "/home/jlo/Pyroot/uione/uienv/lib/python3.5/site-packages/django/utils/functional.py", line 36, in __get__
    res = instance.__dict__[self.name] = self.func(instance)
  File "/home/jlo/Pyroot/uione/uienv/lib/python3.5/site-packages/django/urls/resolvers.py", line 529, in urlconf_module
    return import_module(self.urlconf_name)
  File "/usr/lib/python3.5/importlib/__init__.py", line 126, in import_module
    return _bootstrap._gcd_import(name[level:], package, level)
  File "<frozen importlib._bootstrap>", line 986, in _gcd_import
  File "<frozen importlib._bootstrap>", line 969, in _find_and_load
  File "<frozen importlib._bootstrap>", line 958, in _find_and_load_unlocked
  File "<frozen importlib._bootstrap>", line 673, in _load_unlocked
  File "<frozen importlib._bootstrap_external>", line 665, in exec_module
  File "<frozen importlib._bootstrap>", line 222, in _call_with_frames_removed
  File "/home/jlo/Pyroot/uione/tmsone/tms/urls.py", line 21, in <module>
    path(r'', include('home.urls')),
NameError: name 'include' is not defined
^C(uienv) ]0;jlo@psme-001: ~/Pyroot/uione/tmsonejlo@psme-001:~/Pyroot/uione/tmsone$ ls
db.sqlite3  [0m[01;34mhome[0m  [01;32mmanage.py[0m  outputfile.txt  [01;34mtms[0m  [01;34mtms.cschang[0m  typescript
(uienv) ]0;jlo@psme-001: ~/Pyroot/uione/tmsonejlo@psme-001:~/Pyroot/uione/tmsone$ cd home
(uienv) ]0;jlo@psme-001: ~/Pyroot/uione/tmsone/homejlo@psme-001:~/Pyroot/uione/tmsone/home$ ls
admin.py  __init__.py  models.py    tests.py  views.py
apps.py   [0m[01;34mmigrations[0m   [01;34m__pycache__[0m  urls.py
(uienv) ]0;jlo@psme-001: ~/Pyroot/uione/tmsone/homejlo@psme-001:~/Pyroot/uione/tmsone/home$ ms[Kd[Kkdir templates
(uienv) ]0;jlo@psme-001: ~/Pyroot/uione/tmsone/homejlo@psme-001:~/Pyroot/uione/tmsone/home$ cd [K[K[Kmkdir templates.[K/blog
(uienv) ]0;jlo@psme-001: ~/Pyroot/uione/tmsone/homejlo@psme-001:~/Pyroot/uione/tmsone/home$ mkdir templates/blog[1@r[C[1@m[1P[1P
(uienv) ]0;jlo@psme-001: ~/Pyroot/uione/tmsone/homejlo@psme-001:~/Pyroot/uione/tmsone/home$ rmdir templates/blogmk[C[C[C[C[C[C[C[C[C[C[C[C[C[C[C[C[C[C[K[K[K[Khome
(uienv) ]0;jlo@psme-001: ~/Pyroot/uione/tmsone/homejlo@psme-001:~/Pyroot/uione/tmsone/home$ mkdir templates/homermdir templates/blogmk[C[C[C[C[C[C[C[C[C[C[C[C[C[C[C[C[C[C[Kls[Kcd homels[Kpython manage.py runserver
python: can't open file 'manage.py': [Errno 2] No such file or directory
(uienv) ]0;jlo@psme-001: ~/Pyroot/uione/tmsone/homejlo@psme-001:~/Pyroot/uione/tmsone/home$ cd ..
(uienv) ]0;jlo@psme-001: ~/Pyroot/uione/tmsonejlo@psme-001:~/Pyroot/uione/tmsone$ ls
db.sqlite3  [0m[01;34mhome[0m  [01;32mmanage.py[0m  outputfile.txt  [01;34mtms[0m  [01;34mtms.cschang[0m  typescript
(uienv) ]0;jlo@psme-001: ~/Pyroot/uione/tmsonejlo@psme-001:~/Pyroot/uione/tmsone$ lscd ..python manage.py runserver
Performing system checks...

Unhandled exception in thread started by <function check_errors.<locals>.wrapper at 0x7fea0a6f6ae8>
Traceback (most recent call last):
  File "/home/jlo/Pyroot/uione/uienv/lib/python3.5/site-packages/django/utils/autoreload.py", line 225, in wrapper
    fn(*args, **kwargs)
  File "/home/jlo/Pyroot/uione/uienv/lib/python3.5/site-packages/django/core/management/commands/runserver.py", line 120, in inner_run
    self.check(display_num_errors=True)
  File "/home/jlo/Pyroot/uione/uienv/lib/python3.5/site-packages/django/core/management/base.py", line 364, in check
    include_deployment_checks=include_deployment_checks,
  File "/home/jlo/Pyroot/uione/uienv/lib/python3.5/site-packages/django/core/management/base.py", line 351, in _run_checks
    return checks.run_checks(**kwargs)
  File "/home/jlo/Pyroot/uione/uienv/lib/python3.5/site-packages/django/core/checks/registry.py", line 73, in run_checks
    new_errors = check(app_configs=app_configs)
  File "/home/jlo/Pyroot/uione/uienv/lib/python3.5/site-packages/django/core/checks/urls.py", line 13, in check_url_config
    return check_resolver(resolver)
  File "/home/jlo/Pyroot/uione/uienv/lib/python3.5/site-packages/django/core/checks/urls.py", line 23, in check_resolver
    return check_method()
  File "/home/jlo/Pyroot/uione/uienv/lib/python3.5/site-packages/django/urls/resolvers.py", line 397, in check
    for pattern in self.url_patterns:
  File "/home/jlo/Pyroot/uione/uienv/lib/python3.5/site-packages/django/utils/functional.py", line 36, in __get__
    res = instance.__dict__[self.name] = self.func(instance)
  File "/home/jlo/Pyroot/uione/uienv/lib/python3.5/site-packages/django/urls/resolvers.py", line 536, in url_patterns
    patterns = getattr(self.urlconf_module, "urlpatterns", self.urlconf_module)
  File "/home/jlo/Pyroot/uione/uienv/lib/python3.5/site-packages/django/utils/functional.py", line 36, in __get__
    res = instance.__dict__[self.name] = self.func(instance)
  File "/home/jlo/Pyroot/uione/uienv/lib/python3.5/site-packages/django/urls/resolvers.py", line 529, in urlconf_module
    return import_module(self.urlconf_name)
  File "/usr/lib/python3.5/importlib/__init__.py", line 126, in import_module
    return _bootstrap._gcd_import(name[level:], package, level)
  File "<frozen importlib._bootstrap>", line 986, in _gcd_import
  File "<frozen importlib._bootstrap>", line 969, in _find_and_load
  File "<frozen importlib._bootstrap>", line 958, in _find_and_load_unlocked
  File "<frozen importlib._bootstrap>", line 673, in _load_unlocked
  File "<frozen importlib._bootstrap_external>", line 665, in exec_module
  File "<frozen importlib._bootstrap>", line 222, in _call_with_frames_removed
  File "/home/jlo/Pyroot/uione/tmsone/tms/urls.py", line 21, in <module>
    path(r'', include('home.urls')),
NameError: name 'include' is not defined
^C(uienv) ]0;jlo@psme-001: ~/Pyroot/uione/tmsonejlo@psme-001:~/Pyroot/uione/tmsone$ ptyy[K[K[Kython manage.py shell
Python 3.5.2 (default, Nov 23 2017, 16:37:01) 
[GCC 5.4.0 20160609] on linux
Type "help", "copyright", "credits" or "license" for more information.
(InteractiveConsole)
>>> Post.objects.all()
Traceback (most recent call last):
  File "<console>", line 1, in <module>
NameError: name 'Post' is not defined
>>> exit
Use exit() or Ctrl-D (i.e. EOF) to exit
>>> exit()
(uienv) ]0;jlo@psme-001: ~/Pyroot/uione/tmsonejlo@psme-001:~/Pyroot/uione/tmsone$ 
(uienv) ]0;jlo@psme-001: ~/Pyroot/uione/tmsonejlo@psme-001:~/Pyroot/uione/tmsone$ python[K[K[K[K[K[Kpython =m[K[K-m
Argument expected for the -m option
usage: python [option] ... [-c cmd | -m mod | file | -] [arg] ...
Try `python -h' for more information.
(uienv) ]0;jlo@psme-001: ~/Pyroot/uione/tmsonejlo@psme-001:~/Pyroot/uione/tmsone$ python -m django --version
2.0
(uienv) ]0;jlo@psme-001: ~/Pyroot/uione/tmsonejlo@psme-001:~/Pyroot/uione/tmsone$ cd ..
(uienv) ]0;jlo@psme-001: ~/Pyroot/uionejlo@psme-001:~/Pyroot/uione$ cd ..python -m django --version
2.0
(uienv) ]0;jlo@psme-001: ~/Pyroot/uionejlo@psme-001:~/Pyroot/uione$ python manage.py
Traceback (most recent call last):
  File "manage.py", line 15, in <module>
    execute_from_command_line(sys.argv)
  File "/home/jlo/Pyroot/uione/uienv/lib/python3.5/site-packages/django/core/management/__init__.py", line 371, in execute_from_command_line
    utility.execute()
  File "/home/jlo/Pyroot/uione/uienv/lib/python3.5/site-packages/django/core/management/__init__.py", line 317, in execute
    settings.INSTALLED_APPS
  File "/home/jlo/Pyroot/uione/uienv/lib/python3.5/site-packages/django/conf/__init__.py", line 56, in __getattr__
    self._setup(name)
  File "/home/jlo/Pyroot/uione/uienv/lib/python3.5/site-packages/django/conf/__init__.py", line 43, in _setup
    self._wrapped = Settings(settings_module)
  File "/home/jlo/Pyroot/uione/uienv/lib/python3.5/site-packages/django/conf/__init__.py", line 106, in __init__
    mod = importlib.import_module(self.SETTINGS_MODULE)
  File "/usr/lib/python3.5/importlib/__init__.py", line 126, in import_module
    return _bootstrap._gcd_import(name[level:], package, level)
  File "<frozen importlib._bootstrap>", line 986, in _gcd_import
  File "<frozen importlib._bootstrap>", line 969, in _find_and_load
  File "<frozen importlib._bootstrap>", line 944, in _find_and_load_unlocked
  File "<frozen importlib._bootstrap>", line 222, in _call_with_frames_removed
  File "<frozen importlib._bootstrap>", line 986, in _gcd_import
  File "<frozen importlib._bootstrap>", line 969, in _find_and_load
  File "<frozen importlib._bootstrap>", line 956, in _find_and_load_unlocked
ImportError: No module named 't'
(uienv) ]0;jlo@psme-001: ~/Pyroot/uionejlo@psme-001:~/Pyroot/uione$ ls
db.sqlite3  [0m[01;32mmanage.py[0m  [01;34mnewenv[0m  [01;34mtmsone[0m  typescript  typescript1  [01;34muienv[0m
(uienv) ]0;jlo@psme-001: ~/Pyroot/uionejlo@psme-001:~/Pyroot/uione$ cd tmsone
(uienv) ]0;jlo@psme-001: ~/Pyroot/uione/tmsonejlo@psme-001:~/Pyroot/uione/tmsone$ l;s
db.sqlite3  [0m[01;34mhome[0m/  [01;32mmanage.py[0m*  outputfile.txt  [01;34mtms[0m/  [01;34mtms.cschang[0m/  typescript
s: command not found
(uienv) ]0;jlo@psme-001: ~/Pyroot/uione/tmsonejlo@psme-001:~/Pyroot/uione/tmsone$ ls
db.sqlite3  [0m[01;34mhome[0m  [01;32mmanage.py[0m  outputfile.txt  [01;34mtms[0m  [01;34mtms.cschang[0m  typescript
(uienv) ]0;jlo@psme-001: ~/Pyroot/uione/tmsonejlo@psme-001:~/Pyroot/uione/tmsone$ ls;scd tmsonels[Kpython manage.py

Type 'manage.py help <subcommand>' for help on a specific subcommand.

Available subcommands:

[31m[auth][0m
    changepassword
    createsuperuser

[31m[contenttypes][0m
    remove_stale_contenttypes

[31m[django][0m
    check
    compilemessages
    createcachetable
    dbshell
    diffsettings
    dumpdata
    flush
    inspectdb
    loaddata
    makemessages
    makemigrations
    migrate
    sendtestemail
    shell
    showmigrations
    sqlflush
    sqlmigrate
    sqlsequencereset
    squashmigrations
    startapp
    startproject
    test
    testserver

[31m[sessions][0m
    clearsessions

[31m[staticfiles][0m
    collectstatic
    findstatic
    runserver
(uienv) ]0;jlo@psme-001: ~/Pyroot/uione/tmsonejlo@psme-001:~/Pyroot/uione/tmsone$ python manage.py server[K[K[K[K[K[Krunserver
Performing system checks...

Unhandled exception in thread started by <function check_errors.<locals>.wrapper at 0x7fd9ed205ae8>
Traceback (most recent call last):
  File "/home/jlo/Pyroot/uione/uienv/lib/python3.5/site-packages/django/utils/autoreload.py", line 225, in wrapper
    fn(*args, **kwargs)
  File "/home/jlo/Pyroot/uione/uienv/lib/python3.5/site-packages/django/core/management/commands/runserver.py", line 120, in inner_run
    self.check(display_num_errors=True)
  File "/home/jlo/Pyroot/uione/uienv/lib/python3.5/site-packages/django/core/management/base.py", line 364, in check
    include_deployment_checks=include_deployment_checks,
  File "/home/jlo/Pyroot/uione/uienv/lib/python3.5/site-packages/django/core/management/base.py", line 351, in _run_checks
    return checks.run_checks(**kwargs)
  File "/home/jlo/Pyroot/uione/uienv/lib/python3.5/site-packages/django/core/checks/registry.py", line 73, in run_checks
    new_errors = check(app_configs=app_configs)
  File "/home/jlo/Pyroot/uione/uienv/lib/python3.5/site-packages/django/core/checks/urls.py", line 13, in check_url_config
    return check_resolver(resolver)
  File "/home/jlo/Pyroot/uione/uienv/lib/python3.5/site-packages/django/core/checks/urls.py", line 23, in check_resolver
    return check_method()
  File "/home/jlo/Pyroot/uione/uienv/lib/python3.5/site-packages/django/urls/resolvers.py", line 397, in check
    for pattern in self.url_patterns:
  File "/home/jlo/Pyroot/uione/uienv/lib/python3.5/site-packages/django/utils/functional.py", line 36, in __get__
    res = instance.__dict__[self.name] = self.func(instance)
  File "/home/jlo/Pyroot/uione/uienv/lib/python3.5/site-packages/django/urls/resolvers.py", line 536, in url_patterns
    patterns = getattr(self.urlconf_module, "urlpatterns", self.urlconf_module)
  File "/home/jlo/Pyroot/uione/uienv/lib/python3.5/site-packages/django/utils/functional.py", line 36, in __get__
    res = instance.__dict__[self.name] = self.func(instance)
  File "/home/jlo/Pyroot/uione/uienv/lib/python3.5/site-packages/django/urls/resolvers.py", line 529, in urlconf_module
    return import_module(self.urlconf_name)
  File "/usr/lib/python3.5/importlib/__init__.py", line 126, in import_module
    return _bootstrap._gcd_import(name[level:], package, level)
  File "<frozen importlib._bootstrap>", line 986, in _gcd_import
  File "<frozen importlib._bootstrap>", line 969, in _find_and_load
  File "<frozen importlib._bootstrap>", line 958, in _find_and_load_unlocked
  File "<frozen importlib._bootstrap>", line 673, in _load_unlocked
  File "<frozen importlib._bootstrap_external>", line 665, in exec_module
  File "<frozen importlib._bootstrap>", line 222, in _call_with_frames_removed
  File "/home/jlo/Pyroot/uione/tmsone/tms/urls.py", line 21, in <module>
    path(r'', include('home.urls')),
NameError: name 'include' is not defined

^C(uienv) ]0;jlo@psme-001: ~/Pyroot/uione/tmsonejlo@psme-001:~/Pyroot/uione/tmsone$ pt[Kython --version
Python 3.5.2
(uienv) ]0;jlo@psme-001: ~/Pyroot/uione/tmsonejlo@psme-001:~/Pyroot/uione/tmsone$ django -[K[K-admin --version
2.0
(uienv) ]0;jlo@psme-001: ~/Pyroot/uione/tmsonejlo@psme-001:~/Pyroot/uione/tmsone$ django-admin --version[6Ppytho[C[C[C[C[C[C[C[C[C[C[Cmanage.py runserver
Performing system checks...

Unhandled exception in thread started by <function check_errors.<locals>.wrapper at 0x7f7674f77ae8>
Traceback (most recent call last):
  File "/home/jlo/Pyroot/uione/uienv/lib/python3.5/site-packages/django/utils/autoreload.py", line 225, in wrapper
    fn(*args, **kwargs)
  File "/home/jlo/Pyroot/uione/uienv/lib/python3.5/site-packages/django/core/management/commands/runserver.py", line 120, in inner_run
    self.check(display_num_errors=True)
  File "/home/jlo/Pyroot/uione/uienv/lib/python3.5/site-packages/django/core/management/base.py", line 364, in check
    include_deployment_checks=include_deployment_checks,
  File "/home/jlo/Pyroot/uione/uienv/lib/python3.5/site-packages/django/core/management/base.py", line 351, in _run_checks
    return checks.run_checks(**kwargs)
  File "/home/jlo/Pyroot/uione/uienv/lib/python3.5/site-packages/django/core/checks/registry.py", line 73, in run_checks
    new_errors = check(app_configs=app_configs)
  File "/home/jlo/Pyroot/uione/uienv/lib/python3.5/site-packages/django/core/checks/urls.py", line 40, in check_url_namespaces_unique
    all_namespaces = _load_all_namespaces(resolver)
  File "/home/jlo/Pyroot/uione/uienv/lib/python3.5/site-packages/django/core/checks/urls.py", line 57, in _load_all_namespaces
    url_patterns = getattr(resolver, 'url_patterns', [])
  File "/home/jlo/Pyroot/uione/uienv/lib/python3.5/site-packages/django/utils/functional.py", line 36, in __get__
    res = instance.__dict__[self.name] = self.func(instance)
  File "/home/jlo/Pyroot/uione/uienv/lib/python3.5/site-packages/django/urls/resolvers.py", line 536, in url_patterns
    patterns = getattr(self.urlconf_module, "urlpatterns", self.urlconf_module)
  File "/home/jlo/Pyroot/uione/uienv/lib/python3.5/site-packages/django/utils/functional.py", line 36, in __get__
    res = instance.__dict__[self.name] = self.func(instance)
  File "/home/jlo/Pyroot/uione/uienv/lib/python3.5/site-packages/django/urls/resolvers.py", line 529, in urlconf_module
    return import_module(self.urlconf_name)
  File "/usr/lib/python3.5/importlib/__init__.py", line 126, in import_module
    return _bootstrap._gcd_import(name[level:], package, level)
  File "<frozen importlib._bootstrap>", line 986, in _gcd_import
  File "<frozen importlib._bootstrap>", line 969, in _find_and_load
  File "<frozen importlib._bootstrap>", line 958, in _find_and_load_unlocked
  File "<frozen importlib._bootstrap>", line 673, in _load_unlocked
  File "<frozen importlib._bootstrap_external>", line 665, in exec_module
  File "<frozen importlib._bootstrap>", line 222, in _call_with_frames_removed
  File "/home/jlo/Pyroot/uione/tmsone/tms/urls.py", line 21, in <module>
    path(r'', include('home.urls')),
NameError: name 'include' is not defined
Performing system checks...

System check identified no issues (0 silenced).
December 22, 2017 - 10:44:19
Django version 2.0, using settings 'tms.settings'
Starting development server at http://127.0.0.1:8000/
Quit the server with CONTROL-C.
[31;1mError: That port is already in use.
[0m(uienv) ]0;jlo@psme-001: ~/Pyroot/uione/tmsonejlo@psme-001:~/Pyroot/uione/tmsone$ exit
exit

Script done on ÂªøÂçÅ‰∏ÉÂπ¥ÂçÅ‰∫åÊúàÂªø‰∫åÊó• (ÈÄ±‰∫î) ÂçÅÂÖ´ÊôÇ44ÂàÜ49Áßí
